Traceback (most recent call last):
  File "main.py", line 23, in <module>
    data_train, data_test, label_train, label_test = load_data(users_train, users_test)
  File "/zhome/08/3/117881/BCI_Project/BCI_MI_Classification/dataloader.py", line 21, in load_data
    data_test = { your_key: datasetT[str(your_key)]['data'] for your_key in user_test }
  File "/zhome/08/3/117881/BCI_Project/BCI_MI_Classification/dataloader.py", line 21, in <dictcomp>
    data_test = { your_key: datasetT[str(your_key)]['data'] for your_key in user_test }
KeyError: '5'
